Workbook

Sheet Sheet1
A1: s | B1: 2212453 | C1: g | D1: =MOD(B8, 5) -> 3 | E1: diamonds
A2: d1 | B2: =VALUE(MID($B$1,1,1)) -> 2 | C2: q | D2: =MOD((B3 + B7),3) -> 1 | E2: Precision
A3: d2 | B3: =VALUE(MID($B$1,2,1)) -> 2
A4: d3 | B4: =VALUE(MID($B$1,3,1)) -> 1
A5: d4 | B5: =VALUE(MID($B$1,4,1)) -> 2
A6: d5 | B6: =VALUE(MID($B$1,5,1)) -> 4
A7: d6 | B7: =VALUE(MID($B$1,6,1)) -> 5
A8: d7 | B8: =VALUE(MID(B1,7,1)) -> 3
B10: Màu D là màu phân loại kim cương (D ở đây có nghĩa là màu trong suốt và đắt giá nhất)
A11: STT | B11: Carat > 1.0 | C11: Màu D (D = 1) | D11: Nhãn mục tiêu (Premium = 1)
A12: 1 | B12: 1 | C12: 1 | D12: 1
A13: 2 | B13: 1 | C13: 0 | D13: 1
A14: 3 | B14: 1 | C14: 1 | D14: 1
A15: 4 | B15: 0 | C15: 0 | D15: 1
A16: 5 | B16: 0 | C16: 1 | D16: 0
A17: 6 | B17: 0 | C17: 0 | D17: 0
A18: 7 | B18: 0 | C18: 1 | D18: 0
A19: 8 | B19: 0 | C19: 0 | D19: 0
A22: Mô tả | B22: Ký hiệu | C22: Kết quả
A23: Tổng số mẫu (n) | B23: n | C23: 8
A24: Số mẫu lớp 1 | B24: n1 | C24: =COUNTIF(D12:D19,1) -> 4
A25: Số mẫu lớp 0 | B25: n0 | C25: =COUNTIF($D$12:$D$19,0) -> 4
A26: Xác suất lớp 1 | B26: p1 | C26: =C24/C23 -> 0.5
A27: Xác suất lớp 0 | B27: p0 | C27: =1-C26 -> 0.5
A28: Entropy tổng thể | B28: H(S) | C28: =-C26*LOG(C26,2)-C27*LOG(C27,2) -> 1
A31: BẢNG 3A – PHÉP CHIA A: Theo Carat (> 1.0 =1/ khác - 0)
A32: Nhánh | B32: Số mẫu (nA) | C32: Lớp 1 (n1A) | D32: Lớp 0 (n0A) | E32: p1A | F32: H(nhánh) | G32: Trọng số w = nA/n | H32: w*H
A33: Carat cao (> 1.0 = 1) | B33: =COUNTIF($B$12:$B$19, 1) -> 3 | C33: =COUNTIF($B$12:$B$19, 1) -> 3 | D33: =B33-C33 -> 0 | E33: =C33/B33 -> 1 | F33: =IF(OR(E33=0,E33=1),0,-E33*LOG(E33,2)-(1-E33)*LOG(1-E33,2)) -> 0 | G33: =B33/8 -> 0.375 | H33: =F33*G33 -> 0
A34: Carat thấp (=0) | B34: =COUNTIF($B$12:$B$19, 0) -> 5 | C34: 1 | D34: =B34-C34 -> 4 | E34: =C34/B34 -> 0.2 | F34: =IF(OR(E34=0,E34=1),0,-E34*LOG(E34,2)-(1-E34)*LOG(1-E34,2)) -> 0.72192809 | G34: =B34/8 -> 0.625 | H34: =F34*G34 -> 0.45120506
A35: Tổng H sau chia A | C35: =SUM(H33:H34) -> 0.45120506
A36: Information Gain A (IG) | C36: =C28-C35 -> 0.54879494
A39: BẢNG 3B – PHÉP CHIA B: Theo màu D (Màu D = 1 / Khác=0)
A40: Nhánh | B40: Số mẫu (nA) | C40: Lớp 1 (n1A) | D40: Lớp 0 (n0A) | E40: p1A | F40: H(nhánh) | G40: Trọng số w = nA/n | H40: w*H
A41: Màu D (=1) | B41: =COUNTIF(C12:C19,1) -> 4 | C41: 2 | D41: =B41-C41 -> 2 | E41: =IF(B41=0,0,C41/B41) -> 0.5 | F41: =IF(OR(E41=0,E41=1),0,-E41*LOG(E41,2)-(1-E41)*LOG(1-E41,2)) -> 1 | G41: =IF(B41=0,0,B41/8) -> 0.5 | H41: =F41*G41 -> 0.5
A42: Màu Khác (=0) | B42: =COUNTIF(C12:C19,0) -> 4 | C42: 2 | D42: =B42-C42 -> 2 | E42: =IF(B42=0,0,C42/B42) -> 0.5 | F42: =IF(OR(E42=0,E42=1),0,-E42*LOG(E42,2)-(1-E42)*LOG(1-E42,2)) -> 1 | G42: =IF(B42=0,0,B42/8) -> 0.5 | H42: =F42*G42 -> 0.5
A43: Tổng H sau chia B | C43: =SUM(H41:H42) -> 1
A44: Information Gain B (IG) | C44: =C28-C43 -> 0
A47: BẢNG 4 – SO SÁNH HAI PHÉP CHIA
A48: Phép chia | B48: Đặc trưng | C48: H sau chia | D48: Information Gain | E48: Kết luận
A49: Phép chia A | B49: Carat (cao/thấp) | C49: =Sheet1!C35 -> 0.45120506 | D49: =Sheet1!C36 -> 0.54879494 | E49: =IF(Sheet1!C36<Sheet1!C44,"Kém hơn","Tốt hơn") -> Tốt hơn
...
